Workbook
Name _z3dy4z: '_参数'!$B$2:$D$2
Name _z7qs7z: '_参数'!$B$3:$D$3
Name _zs8gul: '_参数'!$B$4:$J$4
Name _z7rtb0: '_参数'!$B$5:$J$5
Name _zx3hze: '_参数'!$B$6:$J$6
Name _zg5rek: '_参数'!$B$7:$J$7
Name _zvd8oo: '_参数'!$B$8:$J$8
Name _z8uul7: '_参数'!$B$9:$J$9
Name _zmd2n1: '_参数'!$B$10:$J$10
Name _zrss8w: '_参数'!$B$11:$J$11
Name _zxylnr: '_参数'!$B$12:$J$12
Name _zcmix6: '_参数'!$B$13:$J$13
Name _zc9vmb: '_参数'!$B$14:$J$14
Name _zmt7yq: '_参数'!$B$15:$J$15
Name _zgrhmu: '_参数'!$B$16:$J$16
Name _z2124k: '_参数'!$B$17:$J$17
Name _zqq9kl: '_参数'!$B$18:$J$18
Name _z24fjs: '_参数'!$B$19:$J$19
Name _zziz19: '_参数'!$B$20:$J$20
Name _zg9g0j: '_参数'!$B$21:$J$21
Name _zpq4om: '_参数'!$B$22:$J$22
Name _zs2zbw: '_参数'!$B$23:$J$23
Name _zjyrt0: '_参数'!$B$24:$J$24
Name _zy9h20: '_参数'!$B$25:$J$25
Name _zvhtq5: '_参数'!$B$26:$J$26
Name _z8a1yw: '_参数'!$B$27:$J$27
Name _zw9i4c: '_参数'!$B$28:$J$28
Name _z83gdf: '_参数'!$B$29:$J$29
Name _zrngfq: '_参数'!$B$30:$J$30
Name _z34nes: '_参数'!$B$31:$J$31
Name _zsyvua: '_参数'!$B$32:$J$32
Name _ztu197: '_参数'!$B$33:$J$33
Name _zdz3nh: '_参数'!$B$34:$J$34
Name _z59qak: '_参数'!$B$35:$J$35
Name _z7g7nz: '_参数'!$B$36:$J$36
Name _zuo7z3: '_参数'!$B$37:$J$37
Name _zkdmvf: '_参数'!$B$38:$D$38
Name _zt1gjv: '_参数'!$B$39:$D$39
Name _zobook: '测算'!$C$5
Name _zhoj8r: '测算'!$C$7
Name _zqeqjw: '测算'!$C$11
Name _zzg0id: '测算'!$C$12
Name _zv2cfz: '测算'!$C$13
Name _zqixf0: '测算'!$C$14
Name _zh76h3: '测算'!$C$15
Name _zcyms1: '测算'!$C$16
Name _zghrhb: '测算'!$C$17
Name _zecdlb: '测算'!$C$20
Name _z75lzf: '测算'!$C$21
Name _zh30bl: '测算'!$C$22
Name _zfbc18: '测算'!$C$23
Name _zlghw4: '测算'!$C$24
Name _zofnoh: '测算'!$C$25
Name _zzd9na: '测算'!$C$28
Name _zks9j8: '测算'!$C$29
Name _zx0gw6: '测算'!$C$30
Name _z9rhi7: '测算'!$C$31
Name _zva2xn: '测算'!$C$32
Name _z1sub1: '测算'!$C$33
Name _zk03a3: '测算'!$C$34

Sheet 说明
B2: 智能微电网经济评价 v3.3 · 介子九维 JIEZIJIUWEI
B3: 版本 v3.1 · 2026年7月13日 · 说明页补充就近消纳输配电费的1192号文单一容量制公式：就近消纳输配电费 = 容量电价 × 接入容量 × 12 ＋ 输配电度价 × 平均负荷率 × 730 × 12 × 接入容量，便于理解该项费用的构成。本工作簿该路径电价参数已按所选场景预置，此为纯文案说明，不改变计算结果。
B4: 来源：第四监管周期省级输配电价表（附件1），更新日期2026-07-10。区域电网输电价格表（附件2）仅在网站独立查询，不自动计入本测算公式。
B5: 分层测算说明
B6: 电量结构与费用结构（首年电量平衡、购电费、需量电费与收益七分项）按12个月×工作日/休息日共24个典型日的逐小时调度模拟预先算定，收入「测算」表。3个电价场景与3种典型日负荷形态两个选项各自独立、任意组合均已预设结果，用两个下拉选择；场景内的投资、融资、折旧、税务、折现等财务参数均可自由调整，全簿公式即时重算。需要其他电价路径、负荷曲线或资产组合时，请使用介子九维小程序在线测算。
B8: 电价场景
B9: 场景1 参考算例（代理购电·按需量）：山东并网型园区微电网，电网代理购电分时电价，需量计费；引擎参考算例原参数。
B10: 场景2 市场化购电（按需量）：同一资产与负荷，改为市场化交易购电（各档市场购电价+输配等平加），需量计费。
B11: 场景3 代理购电（按容量计费）：同一资产与负荷，代理购电路径，现行容（需）量电费改按变压器容量计费。
B13: 典型日负荷形态
B14: 白天生产型：负荷集中于白班，与光伏出力叠合度高，日间需量峰值明显。
B15: 晚高峰型：负荷晚间抬升，储能放电价值前移，晚间需量峰值最高。
... B39: 需求响应补偿标准、充电服务费、余电上网机制电量比例与结算价等场景内嵌参数为演示取值，正式测算前请通过介子九维小程序按项目所在地核实后重新出数。

Sheet 总览
B1: 智能微电网经济评价 · 总览 | P1: 介子九维 JIEZIJIUWEI
B2: ="所选场景下：税后全投资内部收益率 "&TEXT(_z3ewnh,"0.00%")&"，综合到户电价 "&TEXT(_zmbbnb,"0.000")&" 元/kWh，年节省 "&TEXT(_zbx4ou,"#,##0")&" 万元"
B4: 综合到户电价 | F4: 全投资内部收益率（税后） | J4: 资本金内部收益率 | N4: 静态回收期 | R4: 年节省额
B5: =_zmbbnb | F5: =_z3ewnh | J5: =_z2tbwe | N5: =_z3lcbu | R5: =_zbx4ou
B6: 元/kWh | F6: 主评价指标 | N6: 年 | R6: 万元
B41: 结果随「测算」表输入即时更新；测算口径与边界声明见「说明」。 | P41: 介子九维 JIEZIJIUWEI

Sheet _参数
A1: 典型场景数据
A2: 电价场景 | B2: 参考算例（代理购电·按需量） | C2: 市场化购电（按需量） | D2: 代理购电（按容量计费）
A3: 负荷形态 | B3: 白天生产型 | C3: 晚高峰型 | D3: 连续三班型
A4: 年可用发电量（万kWh） | B4: 1100 | C4: 1100 | D4: 1100 | E4: 1100 | F4: 1100 | G4: 1100 | H4: 1100 | I4: 1100 | J4: 1100
A5: 年自发自用电量（万kWh） | B5: 1100 | C5: 1100 | D5: 1100 | E5: 1100 | F5: 1100 | G5: 1100 | H5: 1100 | I5: 1100 | J5: 1100
A6: 年余电上网电量（万kWh） | B6: 0 | C6: 0 | D6: 0 | E6: 0 | F6: 0 | G6: 0 | H6: 0 | I6: 0 | J6: 0
A7: 年下网购电量（万kWh） | B7: 5142.0395 | C7: 5148.5678 | D7: 5142.796 | E7: 5142.0395 | F7: 5148.5678 | G7: 5142.796 | H7: 5149.14 | I7: 5148.5678 | J7: 5148.775
A8: 柴发年发电量（万kWh） | B8: 0 | C8: 0 | D8: 0 | E8: 0 | F8: 0 | G8: 0 | H8: 0 | I8: 0 | J8: 0
A9: 储能年放电量（万kWh） | B9: 308.28957 | C9: 356.16369 | D9: 313.83725 | E9: 308.28957 | F9: 356.16369 | G9: 313.83725 | H9: 360.36 | I9: 356.16369 | J9: 357.68345
A10: 储能年谷时充电量（万kWh） | B10: 350.32906 | C10: 404.73146 | D10: 356.63323 | E10: 350.32906 | F10: 404.73146 | G10: 356.63323 | H10: 409.5 | I10: 404.73146 | J10: 406.45846
A11: 年总用电量（万kWh） | B11: 6200 | C11: 6200 | D11: 6200 | E11: 6200 | F11: 6200 | G11: 6200 | H11: 6200 | I11: 6200 | J11: 6200
A12: 年购电电度费（万元） | B12: 3303.4162 | C12: 3616.2544 | D12: 3280.1999 | E12: 3060.8975 | F12: 3266.9412 | G12: 3046.945 | H12: 3264.5918 | I12: 3618.2882 | J12: 3250.6221
A13: 年需量（容量）电费（万元） | B13: 386.95339 | C13: 641.435 | D13: 342.144 | E13: 386.95339 | F13: 641.435 | G13: 342.144 | H13: 316.8 | I13: 316.8 | J13: 316.8
A14: 年就近消纳输配电费（万元） | B14: 0 | C14: 0 | D14: 0 | E14: 0 | F14: 0 | G14: 0 | H14: 0 | I14: 0 | J14: 0
A15: 年政府性基金及附加（万元） | B15: 0 | C15: 0 | D15: 0 | E15: 0 | F15: 0 | G15: 0 | H15: 0 | I15: 0 | J15: 0
... A37: 柴发装机（MW） | B37: 2 | C37: 2 | D37: 2 | E37: 2 | F37: 2 | G37: 2 | H37: 2 | I37: 2 | J37: 2
A38: 电价场景说明 | B38: 山东并网型园区微电网，电网代理购电分时电价，需量计费；引擎参考算例原参数。 | C38: 同一资产与负荷，改为市场化交易购电（各档市场购电价+输配等平加），需量计费。 | D38: 同一资产与负荷，代理购电路径，现行容（需）量电费改按变压器容量计费。
A39: 典型日负荷形态说明 | B39: 负荷集中于白班，与光伏出力叠合度高，日间需量峰值明显。 | C39: 负荷晚间抬升，储能放电价值前移，晚间需量峰值最高。 | D39: 24小时平直负荷，需量峰值最低，光伏与负荷叠合度较弱。

Sheet 测算
B1: 智能微电网经济评价 v3.3 · 介子九维 JIEZIJIUWEI
B2: 输入区（黄底蓝字单元格可修改；单元格批注含填报说明）
B3: 参数 | C3: 数值 | D3: 单位 | G3: 关键指标
B4: 场景选择 | G4: 全投资内部收益率（税前） | H4: =_zvfwiv
B5: 电价场景 | C5: 参考算例（代理购电·按需量） | G5: 全投资内部收益率（税后） | H5: =_z3ewnh | I5: 主评价指标
B6: =INDEX(_zkdmvf,MATCH(_zobook,_z3dy4z,0)) | G6: 资本金内部收益率 | H6: =_z2tbwe
B7: 典型日负荷形态 | C7: 白天生产型 | G7: 净现值（税后全投资） | H7: =_z8sr6o | I7: 万元
B8: =INDEX(_zt1gjv,MATCH(_zhoj8r,_z7qs7z,0)) | G8: 静态回收期 | H8: =_z3lcbu | I8: 年
G9: 动态回收期 | H9: =_z4kqsx | I9: 年
B10: A 投资造价 | G10: 度电成本 LCOE | H10: =_zehl1m | I10: 元/kWh
B11: 光伏单位造价 | C11: 3 | D11: 元/W | G11: 综合到户电价 | H11: =_zmbbnb | I11: 元/kWh
B12: 风电单位造价 | C12: 4.5 | D12: 元/W | G12: 年节省额（对照全量电网供电） | H12: =_zbx4ou | I12: 万元
B13: 储能单位造价 | C13: 1 | D13: 元/Wh | G13: 节省率 | H13: =_zisdds
B14: 柴发单位造价 | C14: 0.5 | D14: 元/W
B15: 充电桩投资 | C15: 300 | D15: 万元 | G15: 合规参考（就近就地消纳与可再生占比）
B16: 配电工程等其他投资 | C16: 800 | D16: 万元 | G16: 自用/可用发电量 ≥60% | H16: =_zq9jto | I16: =IF(_zq9jto>=0.6,"满足","不满足")
B17: 其他电源投资 | C17: 0 | D17: 万元 | G17: 可再生装机占比 ≥50% | H17: =_z4zxd3 | I17: =IF(_z4zxd3>=0.5,"满足","不满足")
G18: 自用/年用电量 ≥30% | H18: =_z31n7i | I18: =IF(_z31n7i>=0.3,"满足","不满足")
B19: B 运行参数
B20: 年出力衰减率 | C20: 0.005 | D20: % | G20: 首年电量、费用与收益构成（所选场景）
B21: 储能更换年份 | C21: 12 | D21: 第N年 | G21: 年可用发电量（万kWh） | H21: =_z39asj
B22: 更换费用比例 | C22: 0.5 | D22: % | G22: 年自发自用电量（万kWh） | H22: =_zdj37c
B23: 运维费率 | C23: 0.015 | D23: % | G23: 年余电上网电量（万kWh） | H23: =_zv9i5q
B24: 保险费率 | C24: 0.0025 | D24: % | G24: 年下网购电量（万kWh） | H24: =_zbr0hi
B25: 土地/场地租金（不含税） | C25: 0 | D25: 万元/年 | G25: 柴发年发电量（万kWh） | H25: =_zy2ig8
G26: 储能年放电量（万kWh） | H26: =_z0ernh
B27: C 融资与税务 | G27: 储能年谷时充电量（万kWh） | H27: =_zhfuoj
B28: 资本金比例 | C28: 0.3 | D28: % | G28: 年总用电量（万kWh） | H28: =_zpjfi7
B29: 贷款利率 | C29: 0.045 | D29: % | G29: 年购电电度费（万元） | H29: =_z8pux7
B30: 贷款年限 | C30: 15 | D30: 年 | G30: 年需量（容量）电费（万元） | H30: =_zzcemp
B31: 运营期 | C31: 25 | D31: 年 | G31: 年就近消纳输配电费（万元） | H31: =_zpo09w
B32: 折旧年限 | C32: 20 | D32: 年 | G32: 年政府性基金及附加（万元） | H32: =_z6l4ri
B33: 残值率 | C33: 0.05 | D33: % | G33: 柴发年燃料成本（万元） | H33: =_zdd3mz
B34: 所得税率 | C34: 0.25 | D34: % | G34: 其他电源年成本（万元） | H34: =_z2y4dt
B35: 所得税三免三减半 | C35: 否 | G35: 年综合用电成本（万元） | H35: =_zmkp8w
B36: 可抵扣进项税比例 | C36: 0.1 | D36: % | G36: 综合到户电价（元/kWh） | H36: =_zmbbnb
B37: 基准折现率 | C37: 0.06 | D37: % | G37: 全量电网供电对照成本（万元） | H37: =_z3wzt4
G38: 年节省额（万元） | H38: =_zbx4ou
B39: =IF(_z9rhi7>25,"运营期超过25年上限：年度现金流表最长25年，当前结果不完整，请修改运营期或用介子九维小程序测算","") | G39: 节省率 | H39: =_zisdds
G40: ① 自发自用节省（万元） | H40: =_zgk3lw
...

Sheet _引擎
A1: 标量（引擎口径 2026-07；勿改）
A2: 电价场景序号 | B2: =MATCH(_zobook,_z3dy4z,0)
A3: 负荷形态序号 | B3: =MATCH(_zhoj8r,_z7qs7z,0)
A4: 组合列号 | B4: =(_zy5ipr-1)*3+_zflqft
A5: s_gen_avail | B5: =INDEX(_zs8gul,_zx9tbe)
A6: s_self_use | B6: =INDEX(_z7rtb0,_zx9tbe)
A7: s_export | B7: =INDEX(_zx3hze,_zx9tbe)
A8: s_purchase | B8: =INDEX(_zg5rek,_zx9tbe)
A9: s_diesel_q | B9: =INDEX(_zvd8oo,_zx9tbe)
A10: s_ess_discharge | B10: =INDEX(_z8uul7,_zx9tbe)
A11: s_ess_charge_grid | B11: =INDEX(_zmd2n1,_zx9tbe)
A12: s_total_load | B12: =INDEX(_zrss8w,_zx9tbe)
A13: s_energy_cost | B13: =INDEX(_zxylnr,_zx9tbe)
A14: s_demand_fee | B14: =INDEX(_zcmix6,_zx9tbe)
A15: s_td_fee_1192 | B15: =INDEX(_zc9vmb,_zx9tbe)
A16: s_fund_fee_1192 | B16: =INDEX(_zmt7yq,_zx9tbe)
A17: s_dg_cost | B17: =INDEX(_zgrhmu,_zx9tbe)
A18: s_other_cost | B18: =INDEX(_z2124k,_zx9tbe)
A19: s_user_total | B19: =INDEX(_zqq9kl,_zx9tbe)
A20: s_user_avg_price | B20: =INDEX(_z24fjs,_zx9tbe)
A21: s_baseline | B21: =INDEX(_zziz19,_zx9tbe)
A22: s_saving | B22: =INDEX(_zg9g0j,_zx9tbe)
A23: s_saving_rate | B23: =INDEX(_zpq4om,_zx9tbe)
A24: s_rev_selfuse | B24: =INDEX(_zs2zbw,_zx9tbe)
A25: s_rev_arbitrage | B25: =INDEX(_zjyrt0,_zx9tbe)
A26: s_rev_demand_saving | B26: =INDEX(_zy9h20,_zx9tbe)
A27: s_rev_export | B27: =INDEX(_zvhtq5,_zx9tbe)
A28: s_rev_dr | B28: =INDEX(_z8a1yw,_zx9tbe)
A29: s_rev_ev | B29: =INDEX(_zw9i4c,_zx9tbe)
A30: s_green_avoid | B30: =INDEX(_z83gdf,_zx9tbe)
A31: s_ratio_self_of_gen | B31: =INDEX(_zrngfq,_zx9tbe)
A32: s_ratio_self_of_load | B32: =INDEX(_z34nes,_zx9tbe)
A33: s_re_capacity_share | B33: =INDEX(_zsyvua,_zx9tbe)
A34: s_pv_mw | B34: =INDEX(_ztu197,_zx9tbe)
A35: s_wind_mw | B35: =INDEX(_zdz3nh,_zx9tbe)
A36: s_ess_mw | B36: =INDEX(_z59qak,_zx9tbe)
A37: s_ess_mwh | B37: =INDEX(_z7g7nz,_zx9tbe)
A38: s_dg_mw | B38: =INDEX(_zuo7z3,_zx9tbe)
A39: capex_pv | B39: =_z35787*_zqeqjw*100
A40: capex_wind | B40: =_zm0jdo*_zzg0id*100
...
