Workbook
Name _zqgx7v: '_参数'!$H$3:$H$36
Name _zk618t: '_参数'!$A$3:$A$132
Name _zixjw6: '_参数'!$D$3:$D$132
Name _zwjvbx: '_参数'!$E$3:$E$132
Name _zf8jb3: '_参数'!$F$3:$F$132
Name _zkrpcw: '测算'!$C$5
Name _zlj03i: '测算'!$C$6
Name _z3xkci: '测算'!$C$7
Name _zcshgi: '测算'!$C$8
Name _zhsdpd: '测算'!$C$9
Name _zghnzo: '测算'!$C$12
Name _z82y2b: '测算'!$C$13
Name _zp8xhg: '测算'!$C$14
Name _zx32ce: '测算'!$C$15
Name _zksy9m: '测算'!$C$16
Name _z35wsg: '测算'!$C$20
Name _zix1lp: '测算'!$C$21
Name _z4kl0k: '测算'!$C$22
Name _z98gva: '测算'!$C$23
Name _zrb6fn: '测算'!$C$24
Name _zjttpb: '测算'!$C$25
Name _zbhssj: '测算'!$C$26
Name _zzoaus: '测算'!$C$27
Name _zftf5w: '测算'!$C$30
Name _z6mxd8: '测算'!$C$31
Name _zvtsqd: '测算'!$C$32
Name _zg5443: '测算'!$C$33
Name _zk8d4f: '测算'!$C$36
Name _zhw65s: '测算'!$C$37
Name _zf2rqb: '测算'!$C$38
Name _zsw7bq: '测算'!$C$39
Name _z3m5k2: '测算'!$C$40
Name _z5ctcx: '测算'!$C$41
Name _zysee0: '测算'!$C$42
Name _z78i0e: '测算'!$C$43
Name _zw04od: '测算'!$C$44
Name _z8d2zq: '测算'!$C$45
Name _zzvbgr: '测算'!$C$48
Name _zzl39o: '测算'!$C$49
Name _zm9z4k: '测算'!$C$50
Name _zbf04s: '测算'!$C$51
Name _z1v75m: '测算'!$C$52
Name _zyywx7: '测算'!$C$53
Name _z0ek84: '测算'!$C$54
Name _z7fj0w: '测算'!$C$55
Name _zia8ld: '测算'!$C$56
Name _z5jv12: '测算'!$C$57
Name _zl8371: '测算'!$C$58
Name _z5sfpo: '测算'!$C$59
Name _z7ukau: '测算'!$C$60
Name _zno06c: '测算'!$C$61
Name _ze4vc7: '测算'!$C$62
Name _zqudm6: '测算'!$C$63
Name _z52v2x: '测算'!$C$64
Name _zs8hxw: '测算'!$C$65
Name _zpnfsf: '测算'!$C$66
Name _zawtbl: '测算'!$C$67
Name _ziqmyk: '测算'!$C$68
Name _z0m7ys: '测算'!$C$69
Name _zstij9: '_引擎'!$B$2

Sheet 说明
B2: 绿电直连经济测算 v4.0 · 介子九维 JIEZIJIUWEI
B3: 版本 v4.0 · 2026年8月1日 · 建设期利息与度电成本更换支出口径更新。
B4: 来源：第四监管周期省级输配电价表（附件1），更新日期2026-07-10。区域电网输电价格表（附件2）仅在网站独立查询，不自动计入本测算公式。
B6: 使用方法
B7: 第一步：在「测算」表输入区修改黄底单元格（下拉项从列表选择），其余区域为自动计算。
B8: 第二步：查看结果区的关键指标、合规判定、构成分析与逐年现金流，全簿公式即时重算。
B9: 第三步：需要留存比对的方案，将本文件另存副本后再改参数，避免覆盖原方案。
B10: Excel 版填写内容不会自动保存，填写后请另存为您自己的副本，即可长期保存并随时接着用；网页版与小程序版已支持本机自动留存填写内容。
B12: 测算口径
B13: 财务评价采用融资前（全投资）与融资后（资本金）双口径现金流；投资按含税全额期初流出，现金流入按含税收入、流出扣实缴增值税，可抵扣进项税通过少缴销项逐年回收；折旧计税基数不含可抵扣进项税，年折旧额分母恒用税法折旧年限，期末回收固定资产余值（残值与未折旧账面净值）；更换性支出当年费用化税前扣除、进项税补入抵扣池；亏损按税法结转以后五个年度弥补，全投资与资本金口径各设独立亏损池；三免三减半优惠按光伏、风电投资占比份额化。
B14: 项目总投资含建设期利息，建设期按1年、当年借款按半年计息；建设期利息进入资本金口径资产基础，不进入全投资口径。土地取得费不计提建设期利息，多年建设期暂不支持。
B15: 储能更换支出计入度电成本时按不含可抵扣进项税额的净额，现金流出仍按含税全额。
... B26: 预设参数可直接使用，也可按项目实际逐项修改；正式测算前请结合项目实际核实取值。各参数的含义与填报要点见输入区单元格批注。

Sheet 总览
B1: 绿电直连经济测算 · 总览 | P1: 介子九维 JIEZIJIUWEI
B2: ="当前参数下：税后全投资内部收益率 "&TEXT(_z3ewnh,"0.00%")&"，静态回收期 "&TEXT(_z3lcbu,"0.0")&" 年，年节省 "&TEXT(_zmorcm,"#,##0")&" 万元"
B4: 全投资内部收益率（税后） | F4: 净现值（税后全投资） | J4: 项目总投资（含建设期利息） | N4: 静态回收期 | R4: 度电成本 LCOE
B5: =_z3ewnh | F5: =_z8sr6o | J5: =_z32w4e | N5: =_z3lcbu | R5: =_zehl1m
B6: 主评价指标 | F6: 万元 | J6: 万元 | N6: 年 | R6: 元/kWh
B41: 结果随「测算」表输入即时更新；测算口径与边界声明见「说明」。 | P41: 介子九维 JIEZIJIUWEI

Sheet _参数
A1: 省级电网输配电价矩阵（第四监管周期，附件1）
A2: 键 | B2: 价区 | C2: 电压等级 | D2: 电度电价 | E2: 需量电价 | F2: 容量电价
A3: 北京|1~10(20)千伏 | B3: 北京 | C3: 1~10(20)千伏 | D3: 0.205 | E3: 52 | F3: 33 | H3: 北京
A4: 北京|35千伏 | B4: 北京 | C4: 35千伏 | D4: 0.165 | E4: 48 | F4: 30 | H4: 天津
A5: 北京|110千伏 | B5: 北京 | C5: 110千伏 | D5: 0.165 | E5: 48 | F5: 30 | H5: 河北（南网价区）
A6: 北京|220千伏及以上 | B6: 北京 | C6: 220千伏及以上 | D6: 0.15 | E6: 45 | F6: 28 | H6: 冀北
A7: 天津|1~10(20)千伏 | B7: 天津 | C7: 1~10(20)千伏 | D7: 0.1631 | E7: 43.2 | F7: 27 | H7: 山西
A8: 天津|35千伏 | B8: 天津 | C8: 35千伏 | D8: 0.1402 | E8: 40 | F8: 25 | H8: 蒙东
A9: 天津|110千伏 | B9: 天津 | C9: 110千伏 | D9: 0.1264 | E9: 40 | F9: 25 | H9: 蒙西（内蒙古电力）
A10: 天津|220千伏及以上 | B10: 天津 | C10: 220千伏及以上 | D10: 0.1052 | E10: 36.8 | F10: 23 | H10: 辽宁
A11: 河北（南网价区）|1~10(20)千伏 | B11: 河北（南网价区） | C11: 1~10(20)千伏 | D11: 0.1476 | E11: 35.2 | F11: 22 | H11: 吉林
A12: 河北（南网价区）|35千伏 | B12: 河北（南网价区） | C12: 35千伏 | D12: 0.1226 | E12: 33.6 | F12: 21 | H12: 黑龙江
A13: 河北（南网价区）|110千伏 | B13: 河北（南网价区） | C13: 110千伏 | D13: 0.0976 | E13: 32 | F13: 20 | H13: 上海
A14: 河北（南网价区）|220千伏及以上 | B14: 河北（南网价区） | C14: 220千伏及以上 | D14: 0.0726 | E14: 30.4 | F14: 19 | H14: 江苏
... A36: 吉林|220千伏及以上 | B36: 吉林 | C36: 220千伏及以上 | D36: 0.1113 | E36: 36.8 | F36: 23 | H36: 新疆
A37: 黑龙江|1~10(20)千伏 | B37: 黑龙江 | C37: 1~10(20)千伏 | D37: 0.1385 | E37: 36.8 | F37: 23
A38: 黑龙江|35千伏 | B38: 黑龙江 | C38: 35千伏 | D38: 0.1171 | E38: 36.8 | F38: 23
A39: 黑龙江|110千伏 | B39: 黑龙江 | C39: 110千伏 | D39: 0.1026 | E39: 35.2 | F39: 22
A40: 黑龙江|220千伏及以上 | B40: 黑龙江 | C40: 220千伏及以上 | D40: 0.0763 | E40: 35.2 | F40: 22
A41: 上海|1~10(20)千伏 | B41: 上海 | C41: 1~10(20)千伏 | D41: 0.1623 | E41: 44.8 | F41: 28
A42: 上海|35千伏 | B42: 上海 | C42: 35千伏 | D42: 0.1268 | E42: 41.6 | F42: 26
A43: 上海|110千伏 | B43: 上海 | C43: 110千伏 | D43: 0.0953 | E43: 38.4 | F43: 24
A44: 上海|220千伏及以上 | B44: 上海 | C44: 220千伏及以上 | D44: 0.0851 | E44: 35.2 | F44: 22
A45: 江苏|1~10(20)千伏 | B45: 江苏 | C45: 1~10(20)千伏 | D45: 0.1298 | E45: 51.2 | F45: 32
A46: 江苏|35千伏 | B46: 江苏 | C46: 35千伏 | D46: 0.1048 | E46: 48 | F46: 30
A47: 江苏|110千伏 | B47: 江苏 | C47: 110千伏 | D47: 0.0788 | E47: 44.8 | F47: 28
A48: 江苏|220千伏及以上 | B48: 江苏 | C48: 220千伏及以上 | D48: 0.0518 | E48: 41.6 | F48: 26
... A132: 新疆|220千伏及以上 | B132: 新疆 | C132: 220千伏及以上 | D132: 0.0485 | E132: 30.4 | F132: 19

Sheet 测算
B1: 绿电直连经济测算 v4.0 · 介子九维 JIEZIJIUWEI
B2: 输入区（黄底蓝字可修改；带出值为预设，填「覆盖值」栏替代；批注含填报说明）
B3: 参数 | C3: 数值 | D3: 单位 | E3: 覆盖值 | H3: 关键指标
B4: 模式开关 | H4: 全投资内部收益率（税前） | I4: =_zvfwiv
B5: 项目形态 | C5: 并网型 | H5: 全投资内部收益率（税后） | I5: =_z3ewnh | J5: 主评价指标
B6: 输配电费方式 | C6: 单一容量制 | H6: 资本金内部收益率 | I6: =_z2tbwe
B7: 现行容（需）量电费计费方式 | C7: 按容量 | H7: 净现值（税后全投资） | I7: =_z8sr6o | J7: 万元
B8: 基金计费口径 | C8: 下网+自用 | H8: 静态回收期 | I8: =_z3lcbu | J8: 年
B9: 所得税三免三减半 | C9: 否 | H9: 动态回收期 | I9: =_z4kqsx | J9: 年
H10: 度电成本 LCOE | I10: =_zehl1m | J10: 元/kWh
B11: 价区与输配电价 | H11: 综合到户电价 | I11: =_z3179u | J11: 元/kWh
B12: 价区 | C12: 山东 | H12: 年节省额（对照电网购电） | I12: =_zmorcm | J12: 万元
B13: 接入电压等级 | C13: 110千伏 | H13: 节省率 | I13: =_zhg1yd
B14: 输配电度电价 | C14: =IF(ISNUMBER($E$14),$E$14,IFERROR(INDEX(_zixjw6,MATCH(_zghnzo&"|"&_z82y2b,_zk618t,0)),0)) | D14: 元/kWh | H14: 绿证/CBAM规避价值（单列） | I14: =_zc82pq | J14: 万元
B15: 需量电价 | C15: =IF(ISNUMBER($E$15),$E$15,IFERROR(INDEX(_zwjvbx,MATCH(_zghnzo&"|"&_z82y2b,_zk618t,0)),0)) | D15: 元/kW·月
B16: 容量电价 | C16: =IF(ISNUMBER($E$16),$E$16,IFERROR(INDEX(_zf8jb3,MATCH(_zghnzo&"|"&_z82y2b,_zk618t,0)),0)) | D16: 元/kVA·月 | H16: 合规判定（绿电直连准入红线）
B17: =IF(ISNA(MATCH(_zghnzo&"|"&_z82y2b,_zk618t,0)),"所选价区无此电压档，请改选电压等级或填写覆盖值","") | H17: 自发自用/可用发电量 ≥60% | I17: =_zkt2jm | J17: =IF(_zkt2jm>=0.6,"通过","不满足")
H18: 自发自用/年用电量 ≥30% | I18: =_zy8wik | J18: =IF(_zy8wik>=0.3,"通过","不满足")
B19: A 项目基础 | H19: 上网电量/可用发电量 ≤20% | I19: =_zl0ecr | J19: =IF((_zkrpcw="离网型"),"通过（离网不适用）",IF(_zl0ecr<=0.2,"通过","不满足"))
B20: 光伏装机 | C20: 100 | D20: MW
B21: 光伏年利用小时 | C21: 1100 | D21: h | H21: 投资与费用构成
B22: 风电装机 | C22: 0 | D22: MW | H22: 光伏投资 | I22: =_zkh06o | J22: 万元
B23: 风电年利用小时 | C23: 0 | D23: h | H23: 风电投资 | I23: =_z517d3 | J23: 万元
B24: 储能功率 | C24: 20 | D24: MW | H24: 储能投资 | I24: =_z67r2o | J24: 万元
B25: 储能容量 | C25: 40 | D25: MWh | H25: 专线及升压投资 | I25: =_zbf04s | J25: 万元
B26: 接入公网容量（自主申报） | C26: 25000 | D26: kVA | H26: 土地取得费 | I26: =_z5sfpo | J26: 万元
B27: 申报（合同）最大需量 | C27: 20000 | D27: kW | H27: 建设投资（不含建设期利息） | I27: =_z1tt59 | J27: 万元
H28: 建设期利息 | I28: =_zhc22k | J28: 万元
B29: B 电量 | H29: 项目总投资（含建设期利息） | I29: =_z32w4e | J29: 万元
B30: 用户年用电量 | C30: 12000 | D30: 万kWh | H30: 资本金 | I30: =_zn0hoh | J30: 万元
B31: 年自发自用电量 | C31: 9000 | D31: 万kWh | H31: 贷款 | I31: =_zmqr32 | J31: 万元
B32: 弃电率 | C32: 0.02 | D32: % | H32: 现行容量电费 | I32: =_zektcz | J32: 万元
B33: 年出力衰减率 | C33: 0.005 | D33: % | H33: 输配电量折算费 | I33: =_zdmffp | J33: 万元
H34: 年系统运行费 | I34: =_zqnyts | J34: 万元
B35: C 电价与费用 | H35: 年上网环节线损费 | I35: =_z9r4dl | J35: 万元
B36: 直供电价（协商） | C36: 0.35 | D36: 元/kWh | H36: 年交叉补贴 | I36: =_ze6p1m | J36: 万元
B37: 下网市场购电价 | C37: 0.55 | D37: 元/kWh | H37: 年政府性基金及附加 | I37: =_zpzqxb | J37: 万元
B38: 电网购电对比到户价 | C38: 0.62 | D38: 元/kWh | H38: 年直供电费 | I38: =_zqhyli | J38: 万元
B39: 上网结算均价 | C39: 0.2 | D39: 元/kWh | H39: 年市场购电费 | I39: =_za7fy7 | J39: 万元
B40: 平均负荷率 | C40: 0.55 | D40: % | H40: 年综合用电成本 | I40: =_zvy62p | J40: 万元
...

Sheet _引擎
A1: 标量（引擎口径 2026-07；勿改）
A2: gen_avail | B2: =(_z35wsg*_zix1lp+_z4kl0k*_z98gva)*0.1
A3: gen_net | B3: =_zstij9*(1-_zvtsqd)
A4: self_use | B4: =IF((_zkrpcw="离网型"),MIN(_z6mxd8,_zs8nv3,_zftf5w),MIN(_z6mxd8,_zs8nv3))
A5: export | B5: =IF((_zkrpcw="离网型"),0,MAX(_zs8nv3-_zt11ik,0))
A6: downstream | B6: =IF((_zkrpcw="离网型"),0,MAX(_zftf5w-_zt11ik,0))
A7: ratio_self_gen | B7: =IF(_zstij9>0,_zt11ik/_zstij9,0)
A8: ratio_self_load | B8: =IF(_zftf5w>0,_zt11ik/_zftf5w,0)
A9: ratio_export_gen | B9: =IF(_zstij9>0,_z5gr99/_zstij9,0)
A10: base_cap_fee | B10: =IF((_z3xkci="按需量"),_zx32ce*_zzoaus*12,_zksy9m*_zbhssj*12)
A11: td_fee_cap | B11: =IF((_zkrpcw="离网型"),0,_zm650r/10000)
A12: td_fee_energy | B12: =IF((_zkrpcw="离网型"),0,IF((_zlj03i="单一容量制"),_zp8xhg*_z3m5k2*730*12*_zbhssj/10000,_zp8xhg*(_zsbxps+_zt11ik)))
A13: td_fee | B13: =_zektcz+_zdmffp
A14: sys_fee | B14: =IF((_zkrpcw="离网型"),0,_z5ctcx*_zsbxps)
A15: loss_fee | B15: =IF((_zkrpcw="离网型"),0,_zysee0*_zsbxps)
A16: cross_fee | B16: =IF((_zkrpcw="离网型"),0,_zw04od*_zsbxps)
A17: fund_base | B17: =IF((_zkrpcw="离网型"),_zt11ik,_zsbxps+IF((_zcshgi="下网+自用"),_zt11ik,0))
A18: fund_fee | B18: =_z78i0e*_ztkj9g
A19: cost_direct | B19: =_zk8d4f*_zt11ik
A20: cost_downstream | B20: =_zhw65s*_zsbxps
A21: user_total | B21: =_zqhyli+_za7fy7+_z928ab+_zqnyts+_z9r4dl+_ze6p1m+_zpzqxb
A22: user_avg_price | B22: =IF(_zftf5w>0,_zvy62p/_zftf5w,0)
A23: baseline | B23: =_zf2rqb*_zftf5w
A24: saving | B24: =_zfzfsr-_zvy62p
A25: saving_rate | B25: =IF(_zfzfsr>0,_zmorcm/_zfzfsr,0)
A26: green_avoid | B26: =_z8d2zq*_zt11ik
A27: capex_pv | B27: =_z35wsg*_zzvbgr*100
A28: capex_wind | B28: =_z4kl0k*_zzl39o*100
A29: capex_storage | B29: =_zjttpb*_zm9z4k*100
A30: depreciable_capex | B30: =_zkh06o+_z517d3+_z67r2o+_zbf04s
A31: capex_total | B31: =_zjqqhp+_z5sfpo
A32: idc_denom | B32: =1+_z1v75m*_zyywx7/2
A33: idc_qualifying_total | B33: =_zjqqhp*(1+_zyywx7/2)/_z3lk4m
A34: construction_interest | B34: =_zwp6v3-_zjqqhp
A35: capex_total_with_idc | B35: =_z1tt59+_zhc22k
A36: holiday_share | B36: =IF(_z1tt59>0,(_zkh06o+_z517d3)/_z1tt59,0)
A37: n_years | B37: =ROUND(_z7fj0w,0)
A38: equity | B38: =_z32w4e*_z1v75m
A39: loan | B39: =_z32w4e-_zn0hoh
A40: loan_years_r | B40: =ROUND(_z0ek84,0)
...
